2022-07-19 10:39:14,715 INFO    MainThread:6384 [internal.py:wandb_internal():90] W&B internal server running at pid: 6384, started at: 2022-07-19 10:39:14.715650
2022-07-19 10:39:14,722 INFO    WriterThread:6384 [datastore.py:open_for_write():75] open: C:\Users\Nicor\OneDrive\Documents\KolkowitzLab\Ellipse fitting\Learners\wandb\run-20220719_103912-3v3r7l97\run-3v3r7l97.wandb
2022-07-19 10:39:14,728 DEBUG   SenderThread:6384 [sender.py:send():236] send: header
2022-07-19 10:39:14,728 DEBUG   SenderThread:6384 [sender.py:send():236] send: run
2022-07-19 10:39:42,822 DEBUG   HandlerThread:6384 [handler.py:handle_request():140] handle_request: shutdown
2022-07-19 10:39:42,838 INFO    HandlerThread:6384 [handler.py:finish():806] shutting down handler
2022-07-19 10:39:42,929 INFO    WriterThread:6384 [datastore.py:close():279] close: C:\Users\Nicor\OneDrive\Documents\KolkowitzLab\Ellipse fitting\Learners\wandb\run-20220719_103912-3v3r7l97\run-3v3r7l97.wandb
2022-07-19 10:39:48,233 ERROR   SenderThread:6384 [retry.py:__call__():132] Retry attempt failed:
Traceback (most recent call last):
  File "C:\Users\Nicor\AppData\Local\Programs\Python\Python310\lib\site-packages\urllib3\connectionpool.py", line 449, in _make_request
    six.raise_from(e, None)
  File "<string>", line 3, in raise_from
  File "C:\Users\Nicor\AppData\Local\Programs\Python\Python310\lib\site-packages\urllib3\connectionpool.py", line 444, in _make_request
    httplib_response = conn.getresponse()
  File "C:\Users\Nicor\AppData\Local\Programs\Python\Python310\lib\http\client.py", line 1374, in getresponse
    response.begin()
  File "C:\Users\Nicor\AppData\Local\Programs\Python\Python310\lib\http\client.py", line 318, in begin
    version, status, reason = self._read_status()
  File "C:\Users\Nicor\AppData\Local\Programs\Python\Python310\lib\http\client.py", line 279, in _read_status
    line = str(self.fp.readline(_MAXLINE + 1), "iso-8859-1")
  File "C:\Users\Nicor\AppData\Local\Programs\Python\Python310\lib\socket.py", line 705, in readinto
    return self._sock.recv_into(b)
  File "C:\Users\Nicor\AppData\Local\Programs\Python\Python310\lib\ssl.py", line 1273, in recv_into
    return self.read(nbytes, buffer)
  File "C:\Users\Nicor\AppData\Local\Programs\Python\Python310\lib\ssl.py", line 1129, in read
    return self._sslobj.read(len, buffer)
TimeoutError: The read operation timed out

During handling of the above exception, another exception occurred:

Traceback (most recent call last):
  File "C:\Users\Nicor\AppData\Local\Programs\Python\Python310\lib\site-packages\requests\adapters.py", line 440, in send
    resp = conn.urlopen(
  File "C:\Users\Nicor\AppData\Local\Programs\Python\Python310\lib\site-packages\urllib3\connectionpool.py", line 785, in urlopen
    retries = retries.increment(
  File "C:\Users\Nicor\AppData\Local\Programs\Python\Python310\lib\site-packages\urllib3\util\retry.py", line 550, in increment
    raise six.reraise(type(error), error, _stacktrace)
  File "C:\Users\Nicor\AppData\Local\Programs\Python\Python310\lib\site-packages\urllib3\packages\six.py", line 770, in reraise
    raise value
  File "C:\Users\Nicor\AppData\Local\Programs\Python\Python310\lib\site-packages\urllib3\connectionpool.py", line 703, in urlopen
    httplib_response = self._make_request(
  File "C:\Users\Nicor\AppData\Local\Programs\Python\Python310\lib\site-packages\urllib3\connectionpool.py", line 451, in _make_request
    self._raise_timeout(err=e, url=url, timeout_value=read_timeout)
  File "C:\Users\Nicor\AppData\Local\Programs\Python\Python310\lib\site-packages\urllib3\connectionpool.py", line 340, in _raise_timeout
    raise ReadTimeoutError(
urllib3.exceptions.ReadTimeoutError: HTTPSConnectionPool(host='api.wandb.ai', port=443): Read timed out. (read timeout=10)

During handling of the above exception, another exception occurred:

Traceback (most recent call last):
  File "C:\Users\Nicor\AppData\Local\Programs\Python\Python310\lib\site-packages\wandb\sdk\lib\retry.py", line 108, in __call__
    result = self._call_fn(*args, **kwargs)
  File "C:\Users\Nicor\AppData\Local\Programs\Python\Python310\lib\site-packages\wandb\sdk\internal\internal_api.py", line 158, in execute
    return self.client.execute(*args, **kwargs)
  File "C:\Users\Nicor\AppData\Local\Programs\Python\Python310\lib\site-packages\wandb\vendor\gql-0.2.0\wandb_gql\client.py", line 52, in execute
    result = self._get_result(document, *args, **kwargs)
  File "C:\Users\Nicor\AppData\Local\Programs\Python\Python310\lib\site-packages\wandb\vendor\gql-0.2.0\wandb_gql\client.py", line 60, in _get_result
    return self.transport.execute(document, *args, **kwargs)
  File "C:\Users\Nicor\AppData\Local\Programs\Python\Python310\lib\site-packages\wandb\vendor\gql-0.2.0\wandb_gql\transport\requests.py", line 38, in execute
    request = requests.post(self.url, **post_args)
  File "C:\Users\Nicor\AppData\Local\Programs\Python\Python310\lib\site-packages\requests\api.py", line 117, in post
    return request('post', url, data=data, json=json, **kwargs)
  File "C:\Users\Nicor\AppData\Local\Programs\Python\Python310\lib\site-packages\requests\api.py", line 61, in request
    return session.request(method=method, url=url, **kwargs)
  File "C:\Users\Nicor\AppData\Local\Programs\Python\Python310\lib\site-packages\requests\sessions.py", line 529, in request
    resp = self.send(prep, **send_kwargs)
  File "C:\Users\Nicor\AppData\Local\Programs\Python\Python310\lib\site-packages\requests\sessions.py", line 645, in send
    r = adapter.send(request, **kwargs)
  File "C:\Users\Nicor\AppData\Local\Programs\Python\Python310\lib\site-packages\requests\adapters.py", line 532, in send
    raise ReadTimeout(e, request=request)
requests.exceptions.ReadTimeout: HTTPSConnectionPool(host='api.wandb.ai', port=443): Read timed out. (read timeout=10)
2022-07-19 10:40:42,480 INFO    SenderThread:6384 [dir_watcher.py:__init__():216] watching files in: C:\Users\Nicor\OneDrive\Documents\KolkowitzLab\Ellipse fitting\Learners\wandb\run-20220719_103912-3v3r7l97\files
2022-07-19 10:40:42,480 INFO    SenderThread:6384 [sender.py:_start_run_threads():815] run started: 3v3r7l97 with start time 1658245152
2022-07-19 10:40:42,480 INFO    SenderThread:6384 [sender.py:finish():1114] shutting down sender
2022-07-19 10:40:42,480 INFO    SenderThread:6384 [dir_watcher.py:finish():353] shutting down directory watcher
2022-07-19 10:40:42,482 INFO    SenderThread:6384 [dir_watcher.py:finish():383] scan: C:\Users\Nicor\OneDrive\Documents\KolkowitzLab\Ellipse fitting\Learners\wandb\run-20220719_103912-3v3r7l97\files
2022-07-19 10:40:42,482 INFO    SenderThread:6384 [dir_watcher.py:finish():397] scan save: C:\Users\Nicor\OneDrive\Documents\KolkowitzLab\Ellipse fitting\Learners\wandb\run-20220719_103912-3v3r7l97\files\config.yaml config.yaml
2022-07-19 10:40:42,483 INFO    SenderThread:6384 [file_pusher.py:finish():171] shutting down file pusher
2022-07-19 10:40:42,483 INFO    SenderThread:6384 [file_pusher.py:join():176] waiting for file pusher
2022-07-19 10:40:43,327 INFO    Thread-15 :6384 [upload_job.py:push():138] Uploaded file C:\Users\Nicor\OneDrive\Documents\KolkowitzLab\Ellipse fitting\Learners\wandb\run-20220719_103912-3v3r7l97\files\config.yaml
2022-07-19 10:40:45,036 INFO    MainThread:6384 [internal.py:handle_exit():80] Internal process exited
